Workbook

Sheet Summary

Sheet Efficiency Overlay
A1: AI Infrastructure — Demand vs Supply vs Gap (Efficiency Overlay v4)
A2: Three curves: DEMAND (compute needed after efficiency) | SUPPLY (what can physically be built) | GAP (unmet demand = order book proxy). Blue=input Black=formula Green=Base sheet link Orange=demand Teal=supply Red=gap [n]=source
A3: Row | B3: Units | C3: 2025 | D3: 2026 | E3: 2027 | F3: 2028 | G3: 2029 | H3: 2030 | I3: 2031 | J3: 2032 | K3: 2033 | L3: 2034 | M3: 2035 | N3: 2036 | O3: 2037 | P3: 2038 | Q3: 2039 | R3: 2040 | S3: 2041 | T3: 2042
A4: SECTION 1: GROSS TOKEN DEMAND (Base sheet — taken as given)
A5: Total Tokens/Day (T) | B5: T/day | C5: =Base!B7 -> 124.3022 | D5: =Base!C7 -> 442.23934 | E5: =Base!D7 -> 732.20782 | F5: =Base!E7 -> 1308.8122 | G5: =Base!F7 -> 2093.0444 | H5: =Base!G7 -> 3132.0812 | I5: =Base!H7 -> 4398.7356 | J5: =Base!I7 -> 5697.9389 | ... T5: =Base!S7 -> 22533.007
A6: Enterprise Tokens/Day (T) | B6: T/day | C6: =Base!B10 -> 85 | D6: =Base!C10 -> 373.4475 | E6: =Base!D10 -> 616.06389 | F6: =Base!E10 -> 1120.0042 | G6: =Base!F10 -> 1797.3578 | H6: =Base!G10 -> 2681.7395 | I6: =Base!H10 -> 3750.3096 | J6: =Base!I10 -> 4936.7825 | ... T6: =Base!S10 -> 16778.607
A7: Retail Tokens/Day (T) | B7: T/day | C7: =Base!B9 -> 38.94 | D7: =Base!C9 -> 68.217187 | E7: =Base!D9 -> 115.15334 | F7: =Base!E9 -> 186.96532 | G7: =Base!F9 -> 292.41434 | H7: =Base!G9 -> 445.51066 | I7: =Base!H9 -> 639.10666 | J7: =Base!I9 -> 746.08837 | ... T7: =Base!S9 -> 4607.8331
A8: Robotics Tokens/Day (T) | B8: T/day | C8: =Base!B11 -> 0.3622 | D8: =Base!C11 -> 0.57465 | E8: =Base!D11 -> 0.990586 | F8: =Base!E11 -> 1.8427156 | G8: =Base!F11 -> 3.2722687 | H8: =Base!G11 -> 4.8309945 | I8: =Base!H11 -> 9.319379 | J8: =Base!I11 -> 15.068008 | ... T8: =Base!S11 -> 1146.5666
A9: AI Users (M) | B9: M | C9: =Base!B2 -> 1100 | D9: =Base!C2 -> 1485 | E9: =Base!D2 -> 2004.75 | F9: =Base!E2 -> 2505.9375 | G9: =Base!F2 -> 3132.4219 | H9: =Base!G2 -> 3915.5273 | I9: =Base!H2 -> 4698.6328 | J9: =Base!I2 -> 4657.2778 | ... T9: =Base!S2 -> 7860.7325
A10: Agent Multiplier | B10: x | C10: =Base!B42 -> 2.5 | D10: =Base!C42 -> 3 | E10: =Base!D42 -> 3.5 | F10: =Base!E42 -> 4.5 | G10: =Base!F42 -> 5.5 | H10: =Base!G42 -> 6.5 | I10: =Base!H42 -> 7.5 | J10: =Base!I42 -> 8.5 | ... T10: =Base!S42 -> 14.9
A11: SECTION 2: EFFICIENCY ASSUMPTIONS (yellow = change to test scenarios)
A12: Hardware efficiency = FLOPS per watt, doubling every N years [1][2]. Applied to new capacity only via fleet replacement lag [3]. Existing installed base draws same power until replaced — no retroactive efficiency credit.
A13: Hardware Efficiency Doubling Period (years) [1][2] | B13: yrs | C13: 2 | D13: ← Epoch AI [1]: GPU FLOPS/W doubled ~every 2yrs. Change to 1.5 (bear) or 3 (bull/physics slowdown).
A14: Fleet Replacement Lag — years before installed base upgrades [3] | B14: yrs | C14: 6 | D14: ← Hyperscaler GPU refresh ~4-5yr; enterprise ~7-8yr; DC useful life 20-30yr. Midpoint = 6yr [3].
A15: New Capacity Fraction per Year (1 / fleet lag) | B15: %/yr | C15: =1/C$14 -> 0.16666667 | D15: =1/C$14 -> 0.16666667 | E15: =1/C$14 -> 0.16666667 | F15: =1/C$14 -> 0.16666667 | G15: =1/C$14 -> 0.16666667 | H15: =1/C$14 -> 0.16666667 | I15: =1/C$14 -> 0.16666667 | J15: =1/C$14 -> 0.16666667 | K15: =1/C$14 -> 0.16666667 | L15: =1/C$14 -> 0.16666667 | M15: =1/C$14 -> 0.16666667 | N15: =1/C$14 -> 0.16666667 | O15: =1/C$14 -> 0.16666667 | P15: =1/C$14 -> 0.16666667 | Q15: =1/C$14 -> 0.16666667 | R15: =1/C$14 -> 0.16666667 | S15: =1/C$14 -> 0.16666667 | T15: =1/C$14 -> 0.16666667
A16: Efficiency Index — New Capacity (2025=1.0) | B16: index | C16: 1 | D16: =C16*2^(1/C$13) -> 1.4142136 | E16: =D16*2^(1/C$13) -> 2 | F16: =E16*2^(1/C$13) -> 2.8284271 | G16: =F16*2^(1/C$13) -> 4 | H16: =G16*2^(1/C$13) -> 5.6568542 | I16: =H16*2^(1/C$13) -> 8 | J16: =I16*2^(1/C$13) -> 11.313708 | K16: =J16*2^(1/C$13) -> 16 | L16: =K16*2^(1/C$13) -> 22.627417 | M16: =L16*2^(1/C$13) -> 32 | N16: =M16*2^(1/C$13) -> 45.254834 | O16: =N16*2^(1/C$13) -> 64 | P16: =O16*2^(1/C$13) -> 90.509668 | Q16: =P16*2^(1/C$13) -> 128 | R16: =Q16*2^(1/C$13) -> 181.01934 | S16: =R16*2^(1/C$13) -> 256 | T16: =S16*2^(1/C$13) -> 362.03867
A17: Fleet-Weighted Efficiency Index (new + legacy blend) | B17: index | C17: 1 | D17: =C$15*D16+(1-C$15)*C17 -> 1.0690356 | E17: =C$15*E16+(1-C$15)*D17 -> 1.2241963 | F17: =C$15*F16+(1-C$15)*E17 -> 1.4915681 | G17: =C$15*G16+(1-C$15)*F17 -> 1.9096401 | H17: =C$15*H16+(1-C$15)*G17 -> 2.5341758 | I17: =C$15*I16+(1-C$15)*H17 -> 3.4451465 | J17: =C$15*J16+(1-C$15)*I17 -> 4.7565735 | K17: =C$15*K16+(1-C$15)*J17 -> 6.6304779 | L17: =C$15*L16+(1-C$15)*K17 -> 9.2966344 | M17: =C$15*M16+(1-C$15)*L17 -> 13.080529 | N17: =C$15*N16+(1-C$15)*M17 -> 18.442913 | O17: =C$15*O16+(1-C$15)*N17 -> 26.035761 | P17: =C$15*P16+(1-C$15)*O17 -> 36.781412 | Q17: =C$15*Q16+(1-C$15)*P17 -> 51.98451 | R17: =C$15*R16+(1-C$15)*Q17 -> 73.490314 | S17: =C$15*S16+(1-C$15)*R17 -> 103.9086 | T17: =C$15*T16+(1-C$15)*S17 -> 146.93027
A18: Compute per Token Index — Fleet Weighted (2025=1.0, falls as fleet upgrades) | B18: index | C18: =1/C17 -> 1 | D18: =1/D17 -> 0.93542255 | E18: =1/E17 -> 0.81686244 | F18: =1/F17 -> 0.67043535 | G18: =1/G17 -> 0.52365888 | H18: =1/H17 -> 0.39460562 | I18: =1/I17 -> 0.29026342 | J18: =1/J17 -> 0.21023537 | ... T18: =1/T17 -> 0.0068059493
A19: SECTION 3: DEMAND CURVE — Compute capacity the world NEEDS (orange)
A20: Net compute demand = gross tokens × fleet-weighted compute per token. Floored at prior year — existing infrastructure never demolished. This is WHAT THE WORLD NEEDS, not what will be built.
A21: Net Compute Demand — Total (T tokens equiv/day) | B21: T/day | C21: =C5 -> 124.3022 | D21: =MAX(D5*D18,C21) -> 413.68065 | E21: =MAX(E5*E18,D21) -> 598.11307 | F21: =MAX(F5*F18,E21) -> 877.47396 | G21: =MAX(G5*G18,F21) -> 1096.0413 | H21: =MAX(H5*H18,G21) -> 1235.9368 | I21: =MAX(I5*I18,H21) -> 1276.792 | J21: =MAX(J5*J18,I21) -> 1276.792 | K21: =MAX(K5*K18,J21) -> 1276.792 | ... T21: =MAX(T5*T18,S21) -> 1276.792
A22: Demand Curve — Global GW Required [4][5][6] | B22: GW | C22: 66 | D22: =MAX(C$22*D21/C21,C22) -> 219.64955 | E22: =MAX(C$22*E21/C21,D22) -> 317.57654 | F22: =MAX(C$22*F21/C21,E22) -> 465.90713 | G22: =MAX(C$22*G21/C21,F22) -> 581.95852 | H22: =MAX(C$22*H21/C21,G22) -> 656.23802 | I22: =MAX(C$22*I21/C21,H22) -> 677.93067 | J22: =MAX(C$22*J21/C21,I22) -> 677.93067 | K22: =MAX(C$22*K21/C21,J22) -> 677.93067 | L22: =MAX(C$22*L21/C21,K22) -> 677.93067 | M22: =MAX(C$22*M21/C21,L22) -> 677.93067 | N22: =MAX(C$22*N21/C21,M22) -> 677.93067 | O22: =MAX(C$22*O21/C21,N22) -> 677.93067 | P22: =MAX(C$22*P21/C21,O22) -> 677.93067 | Q22: =MAX(C$22*Q21/C21,P22) -> 677.93067 | R22: =MAX(C$22*R21/C21,Q22) -> 677.93067 | S22: =MAX(C$22*S21/C21,R22) -> 677.93067 | T22: =MAX(C$22*T21/C21,S22) -> 677.93067
A23: Demand Index (2025=100) | B23: idx | C23: =C22/C$22*100 -> 100 | D23: =D22/C$22*100 -> 332.80235 | E23: =E22/C$22*100 -> 481.17657 | F23: =F22/C$22*100 -> 705.91989 | G23: =G22/C$22*100 -> 881.75534 | H23: =H22/C$22*100 -> 994.30003 | I23: =I22/C$22*100 -> 1027.1677 | J23: =J22/C$22*100 -> 1027.1677 | K23: =K22/C$22*100 -> 1027.1677 | L23: =L22/C$22*100 -> 1027.1677 | M23: =M22/C$22*100 -> 1027.1677 | N23: =N22/C$22*100 -> 1027.1677 | O23: =O22/C$22*100 -> 1027.1677 | P23: =P22/C$22*100 -> 1027.1677 | Q23: =Q22/C$22*100 -> 1027.1677 | R23: =R22/C$22*100 -> 1027.1677 | S23: =S22/C$22*100 -> 1027.1677 | T23: =T22/C$22*100 -> 1027.1677
A24: Demand YoY Growth | B24: % | C24: — | D24: =IF(C22=0,0,D22/C22-1) -> 2.3280235 | E24: =IF(D22=0,0,E22/D22-1) -> 0.44583284 | F24: =IF(E22=0,0,F22/E22-1) -> 0.46707037 | G24: =IF(F22=0,0,G22/F22-1) -> 0.24908696 | H24: =IF(G22=0,0,H22/G22-1) -> 0.1276371 | I24: =IF(H22=0,0,I22/H22-1) -> 0.033056072 | J24: =IF(I22=0,0,J22/I22-1) -> 0 | K24: =IF(J22=0,0,K22/J22-1) -> 0 | ... T24: =IF(S22=0,0,T22/S22-1) -> 0
A25: SECTION 4: SUPPLY CURVE — What can PHYSICALLY be built (teal) [7][8]
A26: Supply constrained by transformer lead times (3-5yr), grid interconnection queues (4yr+), permitting, and turbine backlogs — NOT by capital availability. Growth rate accelerates as supply chain investments from 2025-2027 mature. Supply allowed to overshoot demand in outer years to show where air pocket materializes.
A27: Supply Growth Rate 2026-2027 (physically constrained) [7][8] | B27: %/yr | C27: 0.22 | D27: ← ~27GW/yr additions needed to hit JLL 200GW by 2030 [7]. Grid queues 4yr+ cap near-term growth [8].
A28: Supply Growth Rate 2028-2030 (bottlenecks partially clearing) | B28: %/yr | C28: 0.3 | D28: ← Capital committed 2025-2027 materializes. New transformer factories, turbine capacity online.
A29: Supply Growth Rate 2031-2035 (supply chain maturing) | B29: %/yr | C29: 0.25 | D29: ← Infrastructure supply chain at scale. Grid expansion accelerating. Growth sustained but moderating.
A30: Supply Growth Rate 2036-2042 (normalization, potential overshoot) | B30: %/yr | C30: 0.15 | D30: ← Growth moderates. Risk of overshoot as acute shortage resolves. This is where air pocket appears.
A31: Supply Curve — Global GW Operational (what will actually be built) | B31: GW | C31: =C$22 -> 66 | D31: =C31*(1+C$27) -> 80.52 | E31: =D31*(1+C$27) -> 98.2344 | F31: =E31*(1+C$28) -> 127.70472 | G31: =F31*(1+C$28) -> 166.01614 | H31: =G31*(1+C$28) -> 215.82098 | I31: =H31*(1+C$29) -> 269.77622 | J31: =I31*(1+C$29) -> 337.22028 | K31: =J31*(1+C$29) -> 421.52535 | L31: =K31*(1+C$29) -> 526.90668 | M31: =L31*(1+C$29) -> 658.63335 | N31: =M31*(1+C$30) -> 757.42835 | O31: =N31*(1+C$30) -> 871.04261 | P31: =O31*(1+C$30) -> 1001.699 | Q31: =P31*(1+C$30) -> 1151.9538 | R31: =Q31*(1+C$30) -> 1324.7469 | S31: =R31*(1+C$30) -> 1523.459 | T31: =S31*(1+C$30) -> 1751.9778
A32: Supply Index (2025=100) | B32: idx | C32: =C31/C31*100 -> 100 | D32: =D31/C31*100 -> 122 | E32: =E31/C31*100 -> 148.84 | F32: =F31/C31*100 -> 193.492 | G32: =G31/C31*100 -> 251.5396 | H32: =H31/C31*100 -> 327.00148 | I32: =I31/C31*100 -> 408.75185 | J32: =J31/C31*100 -> 510.93981 | K32: =K31/C31*100 -> 638.67477 | L32: =L31/C31*100 -> 798.34346 | M32: =M31/C31*100 -> 997.92932 | N32: =N31/C31*100 -> 1147.6187 | O32: =O31/C31*100 -> 1319.7615 | P32: =P31/C31*100 -> 1517.7258 | Q32: =Q31/C31*100 -> 1745.3846 | R32: =R31/C31*100 -> 2007.1923 | S32: =S31/C31*100 -> 2308.2712 | T32: =T31/C31*100 -> 2654.5118
A33: Supply YoY Growth | B33: % | C33: — | D33: =IF(C31=0,0,D31/C31-1) -> 0.22 | E33: =IF(D31=0,0,E31/D31-1) -> 0.22 | F33: =IF(E31=0,0,F31/E31-1) -> 0.3 | G33: =IF(F31=0,0,G31/F31-1) -> 0.3 | H33: =IF(G31=0,0,H31/G31-1) -> 0.3 | I33: =IF(H31=0,0,I31/H31-1) -> 0.25 | J33: =IF(I31=0,0,J31/I31-1) -> 0.25 | K33: =IF(J31=0,0,K31/J31-1) -> 0.25 | ... T33: =IF(S31=0,0,T31/S31-1) -> 0.15
A34: Incremental Supply Added Each Year (GW) | B34: GW | C34: — | D34: =D31-C31 -> 14.52 | E34: =E31-D31 -> 17.7144 | F34: =F31-E31 -> 29.47032 | G34: =G31-F31 -> 38.311416 | H34: =H31-G31 -> 49.804841 | I34: =I31-H31 -> 53.955244 | J34: =J31-I31 -> 67.444055 | K34: =K31-J31 -> 84.305069 | ... T34: =T31-S31 -> 228.51884
A35: SECTION 5: THE GAP — Unmet Demand = Order Book Proxy (red = opportunity for T10-T15 names)
A36: Positive gap = supply cannot meet demand = transformers, switchgear, line hardware, galvanizing, turbine components all sold out. Gap turning negative = supply overshoots demand = the fiber optic moment. Watch for when incremental supply added per year FALLS — that is when new orders soften, even while backlog remains full.
A37: Gap — Unmet Demand (Demand GW minus Supply GW) | B37: GW | C37: =C22-C31 -> 0 | D37: =D22-D31 -> 139.12955 | E37: =E22-E31 -> 219.34214 | F37: =F22-F31 -> 338.20241 | G37: =G22-G31 -> 415.94239 | H37: =H22-H31 -> 440.41705 | I37: =I22-I31 -> 408.15445 | J37: =J22-J31 -> 340.7104 | ... T37: =T22-T31 -> -1074.0471
A38: Gap as % of Demand (positive = undersupplied, negative = oversupplied) | B38: % | C38: =IF(C22=0,0,C37/C22) -> 0 | D38: =IF(D22=0,0,D37/D22) -> 0.63341606 | E38: =IF(E22=0,0,E37/E22) -> 0.69067488 | F38: =IF(F22=0,0,F37/F22) -> 0.72590091 | G38: =IF(G22=0,0,G37/G22) -> 0.71472858 | H38: =IF(H22=0,0,H37/H22) -> 0.67112394 | I38: =IF(I22=0,0,I37/I22) -> 0.60205928 | J38: =IF(J22=0,0,J37/J22) -> 0.5025741 | ... T38: =IF(T22=0,0,T37/T22) -> -1.5843023
A39: ★ KEY SIGNAL FOR ENERGY NAMES: Watch the row below. When incremental supply additions per year PEAK and begin falling, new equipment orders soften — even while backlog stays full. This leads the gap turning negative by ~2-3 years.
A40: Incremental Demand Added Each Year (GW) — peak = order book peak | B40: GW | C40: — | D40: =MAX(D22-C22,0) -> 153.64955 | E40: =MAX(E22-D22,0) -> 97.926984 | F40: =MAX(F22-E22,0) -> 148.33059 | G40: =MAX(G22-F22,0) -> 116.05139 | H40: =MAX(H22-G22,0) -> 74.2795 | I40: =MAX(I22-H22,0) -> 21.692651 | J40: =MAX(J22-I22,0) -> 0 | K40: =MAX(K22-J22,0) -> 0 | ... T40: =MAX(T22-S22,0) -> 0
...

Sheet Base
B1: 2025 | C1: 2026 | D1: =C1+1 -> 2027 | E1: =D1+1 -> 2028 | F1: =E1+1 -> 2029 | G1: =F1+1 -> 2030 | H1: =G1+1 -> 2031 | I1: =H1+1 -> 2032 | J1: =I1+1 -> 2033 | K1: =J1+1 -> 2034 | ... S1: =R1+1 -> 2042 | T1: Notes
A2: AI Users (M's) | B2: 1100 | C2: =B2*1.35 -> 1485 | D2: =C2*1.35 -> 2004.75 | E2: =D2*1.25 -> 2505.9375 | F2: =E2*1.25 -> 3132.4219 | G2: =F2*1.25 -> 3915.5273 | H2: =G2*1.2 -> 4698.6328 | I2: =I3*I4 -> 4657.2778 | J2: =J3*J4 -> 4969.6737 | K2: =K3*K4 -> 5590.8829 | L2: =L3*L4 -> 5930.8086 | M2: =M3*M4 -> 6282.0949 | N2: =N3*N4 -> 6645.0604 | O2: =O3*O4 -> 6898.9966 | P2: =P3*P4 -> 7160.4323 | ... S2: =S3*S4 -> 7860.7325
A3: Penetration | B3: =B2/B4 -> 0.18333333 | C3: =C2/C4 -> 0.23798077 | D3: =D2/D4 -> 0.30891734 | E3: =E2/E4 -> 0.37857518 | F3: =F2/F4 -> 0.46394017 | G3: =G2/G4 -> 0.56855413 | H3: =H2/H4 -> 0.66888721 | I3: 0.65 | J3: 0.68 | K3: 0.75 | L3: =K3+0.03 -> 0.78 | M3: =L3+0.03 -> 0.81 | N3: =M3+0.03 -> 0.84 | O3: =N3+0.015 -> 0.855 | P3: =O3+0.015 -> 0.87 | Q3: =P3+0.015 -> 0.885 | R3: =Q3+0.015 -> 0.9 | S3: 0.9
A4: Internet Users (M) | B4: 6000 | C4: =B4*1.04 -> 6240 | D4: =C4*1.04 -> 6489.6 | E4: =D4*1.02 -> 6619.392 | F4: =E4*1.02 -> 6751.7798 | G4: =F4*1.02 -> 6886.8154 | H4: =G4*1.02 -> 7024.5517 | I4: =H4*1.02 -> 7165.0428 | J4: =I4*1.02 -> 7308.3436 | K4: =J4*1.02 -> 7454.5105 | L4: =K4*1.02 -> 7603.6007 | ... S4: =R4*1.02 -> 8734.1472
A5: Total Population (M) | B5: =C5*0.99 -> 8217 | C5: 8300 | D5: =C5*1.008 -> 8366.4 | E5: =D5*1.008 -> 8433.3312 | F5: =E5*1.008 -> 8500.7978 | G5: =F5*1.008 -> 8568.8042 | H5: =G5*1.007 -> 8628.7859 | I5: =H5*1.007 -> 8689.1874 | J5: =I5*1.007 -> 8750.0117 | K5: =J5*1.006 -> 8802.5117 | L5: =K5*1.006 -> 8855.3268 | M5: =L5*1.006 -> 8908.4588 | N5: =M5*1.006 -> 8961.9095 | O5: =N5*1.006 -> 9015.681 | P5: =O5*1.006 -> 9069.7751 | Q5: =P5*1.006 -> 9124.1937 | R5: =Q5*1.006 -> 9178.9389 | S5: =R5*1.006 -> 9234.0125
A7: Token Usage (T's)/Day | B7: =SUM(B9:B11) -> 124.3022 | C7: =SUM(C9:C11) -> 442.23934 | D7: =SUM(D9:D11) -> 732.20782 | E7: =SUM(E9:E11) -> 1308.8122 | F7: =SUM(F9:F11) -> 2093.0444 | G7: =SUM(G9:G11) -> 3132.0812 | H7: =SUM(H9:H11) -> 4398.7356 | I7: =SUM(I9:I11) -> 5697.9389 | ... S7: =SUM(S9:S11) -> 22533.007 | T7: =(M7/B7)^0.1-1 -> 0.57815215
C8: =C7/B7-1 -> 2.5577756 | D8: =D7/C7-1 -> 0.65568225 | E8: =E7/D7-1 -> 0.78748732 | F8: =F7/E7-1 -> 0.59919384 | G8: =G7/F7-1 -> 0.49642367 | H8: =H7/G7-1 -> 0.40441303 | I8: =I7/H7-1 -> 0.29535835 | J8: =J7/I7-1 -> 0.24288827 | ... S8: =S7/R7-1 -> 0.087319008
A9: Retail | B9: =B22 -> 38.94 | C9: =C22 -> 68.217187 | D9: =D22 -> 115.15334 | E9: =E22 -> 186.96532 | F9: =F22 -> 292.41434 | G9: =G22 -> 445.51066 | H9: =H22 -> 639.10666 | I9: =I22 -> 746.08837 | ... S9: =S22 -> 4607.8331 | T9: =(S9/B9)^(1/17)-1 -> 0.32418025
A10: Enterprise | B10: =B38 -> 85 | C10: =C38 -> 373.4475 | D10: =D38 -> 616.06389 | E10: =E38 -> 1120.0042 | F10: =F38 -> 1797.3578 | G10: =G38 -> 2681.7395 | H10: =H38 -> 3750.3096 | I10: =I38 -> 4936.7825 | ... S10: =S38 -> 16778.607 | T10: =(S10/B10)^(1/17)-1 -> 0.36464542
A11: Robotics | B11: =B58 -> 0.3622 | C11: =C58 -> 0.57465 | D11: =D58 -> 0.990586 | E11: =E58 -> 1.8427156 | F11: =F58 -> 3.2722687 | G11: =G58 -> 4.8309945 | H11: =H58 -> 9.319379 | I11: =I58 -> 15.068008 | ... S11: =S58 -> 1146.5666 | T11: =(S11/B11)^(1/17)-1 -> 0.60660411
A13: Mix
A14: Retail | B14: =B9/B$7 -> 0.31326879 | C14: =C9/C$7 -> 0.154254 | D14: =D9/D$7 -> 0.15726866 | E14: =E9/E$7 -> 0.14285114 | F14: =F9/F$7 -> 0.13970766 | G14: =G9/G$7 -> 0.1422411 | H14: =H9/H$7 -> 0.14529327 | I14: =I9/I$7 -> 0.13094005 | ... S14: =S9/S$7 -> 0.2044926
A15: Enterprise | B15: =B10/B$7 -> 0.68381734 | C15: =C10/C$7 -> 0.84444659 | D15: =D10/D$7 -> 0.84137847 | E15: =E10/E$7 -> 0.85574093 | F15: =F10/F$7 -> 0.85872894 | G15: =G10/G$7 -> 0.85621648 | H15: =H10/H$7 -> 0.85258808 | I15: =I10/I$7 -> 0.86641549 | ... S15: =S10/S$7 -> 0.74462353
A16: Robotics | B16: =B11/B$7 -> 0.0029138664 | C16: =C11/C$7 -> 0.0012994095 | D16: =D11/D$7 -> 0.0013528755 | E16: =E11/E$7 -> 0.0014079297 | F16: =F11/F$7 -> 0.0015634015 | G16: =G11/G$7 -> 0.0015424232 | H16: =H11/H$7 -> 0.0021186495 | I16: =I11/I$7 -> 0.0026444664 | ... S16: =S11/S$7 -> 0.05088387
A18: Retail
A19: Total Tokens (B's) per year | B19: =(B22+B38)*365 -> 45238.1 | C19: =(C22+C38)*365 -> 161207.61 | D19: =(D22+D38)*365 -> 266894.29 | E19: =(E22+E38)*365 -> 477043.86 | F19: =(F22+F38)*365 -> 762766.82 | G19: =(G22+G38)*365 -> 1141446.3 | H19: =(H22+H38)*365 -> 1602136.9 | I19: =(I22+I38)*365 -> 2074247.9 | ... S19: =(S22+S38)*365 -> 7806050.7 | T19: 10Y CAGR
A20: Growth | C20: =C19/B19-1 -> 2.5635363 | D20: =D19/C19-1 -> 0.65559361 | E20: =E19/D19-1 -> 0.78738877 | F20: =F19/E19-1 -> 0.59894486 | G20: =G19/F19-1 -> 0.49645511 | H20: =H19/G19-1 -> 0.40360252 | I20: =I19/H19-1 -> 0.29467578 | J20: =J19/I19-1 -> 0.24174065 | ... S20: =S19/R19-1 -> 0.075613675 | T20: =(M19/B19)^0.1-1 -> 0.57723604
A22: Use per day (T's) | B22: =B23*((B2))*0.000001 -> 38.94 | C22: =C23*((C2))*0.000001 -> 68.217187 | D22: =D23*((D2))*0.000001 -> 115.15334 | E22: =E23*((E2))*0.000001 -> 186.96532 | F22: =F23*((F2))*0.000001 -> 292.41434 | G22: =G23*((G2))*0.000001 -> 445.51066 | H22: =H23*((H2))*0.000001 -> 639.10666 | I22: =I23*((I2))*0.000001 -> 746.08837 | ... S22: =S23*((S2))*0.000001 -> 4607.8331
A23: User Breakdown (tokens/day) | B23: =(SUMPRODUCT(B24:B27,B31:B34))*B28 -> 35400 | C23: =SUMPRODUCT(C24:C27,C31:C34)*C28 -> 45937.5 | D23: =SUMPRODUCT(D24:D27,D31:D34)*D28 -> 57440.25 | E23: =SUMPRODUCT(E24:E27,E31:E34)*E28 -> 74608.931 | F23: =SUMPRODUCT(F24:F27,F31:F34)*F28 -> 93350.88 | G23: =SUMPRODUCT(G24:G27,G31:G34)*G28 -> 113780.5 | H23: =SUMPRODUCT(H24:H27,H31:H34)*H28 -> 136019.71 | I23: =SUMPRODUCT(I24:I27,I31:I34)*I28 -> 160198.38 | J23: =SUMPRODUCT(J24:J27,J31:J34)*J28 -> 186454.88 | ... S23: =SUMPRODUCT(S24:S27,S31:S34)*S28 -> 586183.68 | T23: =(M23/B23)^0.1-1 -> 0.2401154
A24: Casual | B24: 2000 | C24: 2000 | D24: 2000 | E24: 2000 | F24: 2000 | G24: 2000 | H24: 2000 | I24: 2000 | J24: 2000 | K24: 2000 | L24: 2000 | M24: 2000 | N24: 2000 | O24: 2000 | P24: 2000 | Q24: 2000 | R24: 2000 | S24: 2000 | T24: 2-5 per week
A25: Regular | B25: 15000 | C25: 15000 | D25: 15000 | E25: 15000 | F25: 15000 | G25: 15000 | H25: 15000 | I25: 15000 | J25: 15000 | K25: 15000 | L25: 15000 | M25: 15000 | N25: 15000 | O25: 15000 | P25: 15000 | Q25: 15000 | R25: 15000 | S25: 15000 | T25: 5-10 queries per day
A26: Power | B26: 200000 | C26: 200000 | D26: 200000 | E26: 200000 | F26: 200000 | G26: 200000 | H26: 200000 | I26: 200000 | J26: 200000 | K26: 200000 | L26: 200000 | M26: 200000 | N26: 200000 | O26: 200000 | P26: 200000 | Q26: 200000 | R26: 200000 | S26: 200000 | T26: 2-3 hours
A27: Pro/Prosumer | B27: 1000000 | C27: 1000000 | D27: 1000000 | E27: 1000000 | F27: 1000000 | G27: 1000000 | H27: 1000000 | I27: 1000000 | J27: 1000000 | K27: 1000000 | L27: 1000000 | M27: 1000000 | N27: 1000000 | O27: 1000000 | P27: 1000000 | Q27: 1000000 | R27: 1000000 | S27: 1000000 | T27: some claude code or heavy research
A28: Background multiplier | B28: 1 | C28: =B28*1.05 -> 1.05 | D28: =C28*1.05 -> 1.1025 | E28: =D28*1.05 -> 1.157625 | F28: =E28*1.05 -> 1.2155063 | G28: =F28*1.05 -> 1.2762816 | H28: =G28*1.05 -> 1.3400956 | I28: =H28*1.05 -> 1.4071004 | J28: =I28*1.05 -> 1.4774554 | ... S28: =R28*1.05 -> 2.2920183 | T28: Background tokens not even aware of
A30: Mix
A31: Casual | B31: 0.8 | C31: =B31-0.05 -> 0.75 | D31: =C31-0.05 -> 0.7 | E31: =D31-0.05 -> 0.65 | F31: =E31-0.05 -> 0.6 | G31: =F31-0.05 -> 0.55 | H31: =G31-0.05 -> 0.5 | I31: =H31-0.05 -> 0.45 | J31: =I31-0.05 -> 0.4 | ... O31: =N31-0.05 -> 0.15 | P31: 0.1 | Q31: 0.1 | R31: 0.1 | S31: 0.1
A32: Regular | B32: 0.12 | C32: =B32+0.03 -> 0.15 | D32: =C32+0.03 -> 0.18 | E32: =D32+0.03 -> 0.21 | F32: =E32+0.03 -> 0.24 | G32: =F32+0.03 -> 0.27 | H32: =G32+0.03 -> 0.3 | I32: =H32+0.03 -> 0.33 | J32: =I32+0.03 -> 0.36 | K32: =J32+0.01 -> 0.37 | L32: 0.37 | M32: 0.37 | N32: 0.37 | O32: 0.37 | P32: 0.37 | Q32: 0.37 | R32: 0.37 | S32: 0.37
A33: Power | B33: 0.06 | C33: =1-C31-C32-C34 -> 0.075 | D33: =1-D31-D32-D34 -> 0.09 | E33: =1-E31-E32-E34 -> 0.1 | F33: =1-F31-F32-F34 -> 0.11 | G33: =1-G31-G32-G34 -> 0.12 | H33: =1-H31-H32-H34 -> 0.13 | I33: =1-I31-I32-I34 -> 0.14 | J33: =1-J31-J32-J34 -> 0.15 | ... S33: =1-S31-S32-S34 -> 0.35
A34: Pro/Prosumer | B34: 0.02 | C34: =B34+0.005 -> 0.025 | D34: =C34+0.005 -> 0.03 | E34: =D34+0.01 -> 0.04 | F34: =E34+0.01 -> 0.05 | G34: =F34+0.01 -> 0.06 | H34: =G34+0.01 -> 0.07 | I34: =H34+0.01 -> 0.08 | J34: =I34+0.01 -> 0.09 | K34: =J34+0.01 -> 0.1 | L34: =K34+0.01 -> 0.11 | ... S34: =R34+0.01 -> 0.18
A35: Background
A37: Total Tokens (T's) per year | B37: =B38*365 -> 31025 | C37: =C38*365 -> 136308.34 | D37: =D38*365 -> 224863.32 | E37: =E38*365 -> 408801.52 | F37: =F38*365 -> 656035.59 | G37: =G38*365 -> 978834.92 | H37: =H38*365 -> 1368863 | I37: =I38*365 -> 1801925.6 | ... S37: =S38*365 -> 6124191.6
A38: Enterprise Used Per Day (T) | B38: 85 | C38: =C39*C40*0.001*C42 -> 373.4475 | D38: =D39*D40*0.001*D42 -> 616.06389 | E38: =E39*E40*0.001*E42 -> 1120.0042 | F38: =F39*F40*0.001*F42 -> 1797.3578 | G38: =G39*G40*0.001*G42 -> 2681.7395 | H38: =H39*H40*0.001*H42 -> 3750.3096 | I38: =I39*I40*0.001*I42 -> 4936.7825 | J38: =J39*J40*0.001*J42 -> 6130.0319 | ... S38: =S39*S40*0.001*S42 -> 16778.607 | T38: =(M38/B38)^0.1-1 -> 0.60916163
A39: Knowledge Workers (M) | B39: 1250 | C39: =B39*1.01 -> 1262.5 | D39: =C39*1.01 -> 1275.125 | E39: =D39*1.01 -> 1287.8763 | F39: =E39*1.01 -> 1300.755 | G39: =F39*1.01 -> 1313.7626 | H39: =G39*1.01 -> 1326.9002 | I39: =H39*1.01 -> 1340.1692 | J39: =I39*1.01 -> 1353.5709 | ... S39: =R39*1.01 -> 1480.3805
A40: Tokens/worker per/day | B40: =B38/(B39/1000) -> 68 | C40: =B40*(1+C41) -> 98.6 | D40: =C40*(1+D41) -> 138.04 | E40: =D40*(1+E41) -> 193.256 | F40: =E40*(1+F41) -> 251.2328 | G40: =F40*(1+G41) -> 314.041 | H40: =G40*(1+H41) -> 376.8492 | I40: =H40*(1+I41) -> 433.37658 | J40: =I40*(1+J41) -> 476.71424 | ... S40: =R40*(1+S41) -> 760.66997
A41: Intensity Growth | C41: 0.45 | D41: 0.4 | E41: 0.4 | F41: 0.3 | G41: 0.25 | H41: 0.2 | I41: 0.15 | J41: 0.1 | K41: 0.08 | L41: 0.05 | M41: 0.05 | N41: 0.05 | O41: 0.05 | P41: 0.05 | Q41: 0.05 | R41: 0.05 | S41: 0.05
A42: Agent Multiplier | B42: 2.5 | C42: =B42+0.5 -> 3 | D42: =C42+0.5 -> 3.5 | E42: =D42+1 -> 4.5 | F42: =E42+1 -> 5.5 | G42: =F42+1 -> 6.5 | H42: =G42+1 -> 7.5 | I42: =H42+1 -> 8.5 | J42: =I42+1 -> 9.5 | K42: =J42+1 -> 10.5 | L42: =K42+1 -> 11.5 | ... O42: =N42+1 -> 14.5 | P42: =O42+0.1 -> 14.6 | Q42: =P42+0.1 -> 14.7 | R42: =Q42+0.1 -> 14.8 | S42: =R42+0.1 -> 14.9 | T42: This could be much higher
A45: Robotics and Machines
A47: Breakdown of Robots (M's)
A48: AV | B48: 0.01 | C48: 0.05 | D48: 0.15 | E48: 0.5 | F48: 1 | G48: 1.5 | H48: =AVERAGE(I48,G48) -> 2.55 | I48: 3.6 | J48: =AVERAGE(K48,I48) -> 7.65 | K48: 11.7 | L48: =AVERAGE(M48,K48) -> 17.9 | M48: 24.1 | N48: =AVERAGE(O48,M48) -> 31.65 | O48: 39.2 | P48: =AVERAGE(Q48,O48) -> 49.15 | Q48: 59.1 | R48: =AVERAGE(S48,Q48) -> 66.15 | S48: 73.2
A49: Home Robots | B49: 13.8 | C49: 15.5 | D49: 24.8 | E49: 26.5 | F49: 38.2 | G49: 41.8 | H49: =AVERAGE(I49,G49) -> 46.55 | I49: 51.3 | J49: =AVERAGE(K49,I49) -> 56.25 | K49: 61.2 | L49: =AVERAGE(M49,K49) -> 81.05 | M49: 100.9 | N49: =AVERAGE(O49,M49) -> 118.65 | O49: 136.4 | P49: =AVERAGE(Q49,O49) -> 170.55 | Q49: 204.7 | R49: =AVERAGE(S49,Q49) -> 248.2 | S49: 291.7
...

Sheet Robo Bull
B1: 2025 | C1: 2026 | D1: =C1+1 -> 2027 | E1: =D1+1 -> 2028 | F1: =E1+1 -> 2029 | G1: =F1+1 -> 2030 | H1: =G1+1 -> 2031 | I1: =H1+1 -> 2032 | J1: =I1+1 -> 2033 | K1: =J1+1 -> 2034 | ... S1: =R1+1 -> 2042 | T1: Notes
A2: AI Users (M's) | B2: 900 | C2: =B2*1.3 -> 1170 | D2: =C2*1.3 -> 1521 | E2: =D2*1.25 -> 1901.25 | F2: =E2*1.25 -> 2376.5625 | G2: =F2*1.25 -> 2970.7031 | H2: =G2*1.2 -> 3564.8438 | I2: =I3*I4 -> 4299.0257 | J2: =I2*1.1 -> 4728.9282 | K2: =J2*1.1 -> 5201.8211 | L2: =K2*1.1 -> 5722.0032 | M2: =L2*1.1 -> 6294.2035 | N2: =M2*1.1 -> 6923.6238 | O2: =N2*1.1 -> 7615.9862 | P2: =O2*1.1 -> 8377.5848 | Q2: =P2*1.1 -> 9215.3433 | ... S2: =R2*1.1 -> 11150.565
A3: Penetration | B3: =B2/B4 -> 0.15 | C3: =C2/C4 -> 0.1875 | D3: =D2/D4 -> 0.234375 | E3: =E2/E4 -> 0.28722426 | F3: =F2/F4 -> 0.35199052 | G3: =G2/G4 -> 0.43136093 | H3: =H2/H4 -> 0.50748345 | I3: 0.6 | J3: 0.68 | K3: 0.75 | L3: =K3+0.03 -> 0.78 | M3: =L3+0.03 -> 0.81 | N3: =M3+0.03 -> 0.84 | O3: =N3+0.015 -> 0.855 | P3: =O3+0.015 -> 0.87 | Q3: =P3+0.015 -> 0.885 | R3: =Q3+0.015 -> 0.9 | S3: =R3+0.015 -> 0.915
A4: Internet Users (M) | B4: 6000 | C4: =B4*1.04 -> 6240 | D4: =C4*1.04 -> 6489.6 | E4: =D4*1.02 -> 6619.392 | F4: =E4*1.02 -> 6751.7798 | G4: =F4*1.02 -> 6886.8154 | H4: =G4*1.02 -> 7024.5517 | I4: =H4*1.02 -> 7165.0428 | J4: =I4*1.02 -> 7308.3436 | K4: =J4*1.02 -> 7454.5105 | L4: =K4*1.02 -> 7603.6007 | ... S4: =R4*1.02 -> 8734.1472
A5: Total Population (M) | B5: =C5*0.99 -> 8217 | C5: 8300 | D5: =C5*1.008 -> 8366.4 | E5: =D5*1.008 -> 8433.3312 | F5: =E5*1.008 -> 8500.7978 | G5: =F5*1.008 -> 8568.8042 | H5: =G5*1.007 -> 8628.7859 | I5: =H5*1.007 -> 8689.1874 | J5: =I5*1.007 -> 8750.0117 | K5: =J5*1.006 -> 8802.5117 | L5: =K5*1.006 -> 8855.3268 | M5: =L5*1.006 -> 8908.4588 | N5: =M5*1.006 -> 8961.9095 | O5: =N5*1.006 -> 9015.681 | P5: =O5*1.006 -> 9069.7751 | Q5: =P5*1.006 -> 9124.1937 | R5: =Q5*1.006 -> 9178.9389 | S5: =R5*1.006 -> 9234.0125
A7: Token Usage (T's)/Day | B7: =SUM(B9:B11) -> 53.4622 | C7: =SUM(C9:C11) -> 107.76694 | D7: =SUM(D9:D11) -> 199.90244 | E7: =SUM(E9:E11) -> 396.64342 | F7: =SUM(F9:F11) -> 709.32542 | G7: =SUM(G9:G11) -> 1175.6067 | H7: =SUM(H9:H11) -> 1815.0911 | I7: =SUM(I9:I11) -> 2658.889 | ... S7: =SUM(S9:S11) -> 66867.69 | T7: =(M7/B7)^0.1-1 -> 0.64455214
C8: =C7/B7-1 -> 1.0157595 | D8: =D7/C7-1 -> 0.85495148 | E8: =E7/D7-1 -> 0.98418497 | F8: =F7/E7-1 -> 0.78832017 | G8: =G7/F7-1 -> 0.65735869 | H8: =H7/G7-1 -> 0.54396125 | I8: =I7/H7-1 -> 0.4648791 | J8: =J7/I7-1 -> 0.36969127 | ... S8: =S7/R7-1 -> 0.47371715
A9: Retail | B9: =B22 -> 26.55 | C9: =C22 -> 44.84025 | D9: =D22 -> 72.945259 | E9: =E22 -> 118.02511 | F9: =F22 -> 184.15632 | G9: =G22 -> 280.09364 | H9: =H22 -> 401.28745 | I9: =I22 -> 569.37726 | ... S9: =S22 -> 5834.7316 | T9: =(S9/B9)^(1/17)-1 -> 0.37328962
A10: Enterprise | B10: =B38 -> 26.55 | C10: =C38 -> 62.346037 | D10: =D38 -> 125.939 | E10: =E38 -> 276.65649 | F10: =F38 -> 521.5897 | G10: =G38 -> 888.98445 | H10: =H38 -> 1400.6839 | I10: =I38 -> 2063.0907 | ... S10: =S38 -> 12159.459 | T10: =(S10/B10)^(1/17)-1 -> 0.43390564
A11: Robotics | B11: =B58 -> 0.3622 | C11: =C58 -> 0.58065 | D11: =D58 -> 1.018186 | E11: =E58 -> 1.9618156 | F11: =F58 -> 3.5794047 | G11: =G58 -> 6.5285705 | H11: =H58 -> 13.119775 | I11: =I58 -> 26.421124 | ... S11: =S58 -> 48873.499 | T11: =(S11/B11)^(1/17)-1 -> 1.0034202
A13: Mix
A14: Retail | B14: =B9/B$7 -> 0.49661256 | C14: =C9/C$7 -> 0.41608541 | D14: =D9/D$7 -> 0.36490429 | E14: =E9/E$7 -> 0.29755974 | F14: =F9/F$7 -> 0.25962177 | G14: =G9/G$7 -> 0.23825455 | H14: =H9/H$7 -> 0.22108392 | I14: =I9/I$7 -> 0.21414104 | ... S14: =S9/S$7 -> 0.087257861
A15: Enterprise | B15: =B10/B$7 -> 0.49661256 | C15: =C10/C$7 -> 0.57852658 | D15: =D10/D$7 -> 0.63000229 | E15: =E10/E$7 -> 0.69749421 | F15: =F10/F$7 -> 0.73533202 | G15: =G10/G$7 -> 0.75619208 | H15: =H10/H$7 -> 0.77168792 | I15: =I10/I$7 -> 0.77592206 | ... S15: =S10/S$7 -> 0.18184356
A16: Robotics | B16: =B11/B$7 -> 0.0067748802 | C16: =C11/C$7 -> 0.0053880162 | D16: =D11/D$7 -> 0.0050934146 | E16: =E11/E$7 -> 0.0049460434 | F16: =F11/F$7 -> 0.0050462095 | G16: =G11/G$7 -> 0.005553363 | H16: =H11/H$7 -> 0.0072281631 | I16: =I11/I$7 -> 0.0099369037 | ... S16: =S11/S$7 -> 0.73089858
A18: Retail
A19: Total Tokens (B's) per year | B19: =(B22+B38)*365 -> 19381.5 | C19: =(C22+C38)*365 -> 39122.995 | D19: =(D22+D38)*365 -> 72592.753 | E19: =(E22+E38)*365 -> 144058.79 | F19: =(F22+F38)*365 -> 257597.3 | G19: =(G22+G38)*365 -> 426713.5 | H19: =(H22+H38)*365 -> 657719.54 | I19: =(I22+I38)*365 -> 960850.79 | ... S19: =(S22+S38)*365 -> 6567879.6 | T19: 10Y CAGR
A20: Growth | C20: =C19/B19-1 -> 1.0185742 | D20: =D19/C19-1 -> 0.85550091 | E20: =E19/D19-1 -> 0.98447888 | F20: =F19/E19-1 -> 0.78814015 | G20: =G19/F19-1 -> 0.65651389 | H20: =H19/G19-1 -> 0.54136098 | I20: =I19/H19-1 -> 0.46088223 | J20: =J19/I19-1 -> 0.36223775 | ... S20: =S19/R19-1 -> 0.14578084 | T20: =(M19/B19)^0.1-1 -> 0.63202189
A22: Use per day (T's) | B22: =B23*((B2))*0.000001 -> 26.55 | C22: =C23*((C2))*0.000001 -> 44.84025 | D22: =D23*((D2))*0.000001 -> 72.945259 | E22: =E23*((E2))*0.000001 -> 118.02511 | F22: =F23*((F2))*0.000001 -> 184.15632 | G22: =G23*((G2))*0.000001 -> 280.09364 | H22: =H23*((H2))*0.000001 -> 401.28745 | I22: =I23*((I2))*0.000001 -> 569.37726 | ... S22: =S23*((S2))*0.000001 -> 5834.7316
A23: User Breakdown (tokens/day) | B23: =(SUMPRODUCT(B24:B27,B31:B34))*B28 -> 29500 | C23: =SUMPRODUCT(C24:C27,C31:C34)*C28 -> 38325 | D23: =SUMPRODUCT(D24:D27,D31:D34)*D28 -> 47958.75 | E23: =SUMPRODUCT(E24:E27,E31:E34)*E28 -> 62077.641 | F23: =SUMPRODUCT(F24:F27,F31:F34)*F28 -> 77488.523 | G23: =SUMPRODUCT(G24:G27,G31:G34)*G28 -> 94285.3 | H23: =SUMPRODUCT(H24:H27,H31:H34)*H28 -> 112568.03 | I23: =SUMPRODUCT(I24:I27,I31:I34)*I28 -> 132443.33 | J23: =SUMPRODUCT(J24:J27,J31:J34)*J28 -> 154024.73 | ... S23: =SUMPRODUCT(S24:S27,S31:S34)*S28 -> 523267.78 | T23: =(M23/B23)^0.1-1 -> 0.23931909
A24: Casual | B24: 1500 | C24: 1500 | D24: 1500 | E24: 1500 | F24: 1500 | G24: 1500 | H24: 1500 | I24: 1500 | J24: 1500 | K24: 1500 | L24: 1500 | M24: 1500 | N24: 1500 | O24: 1500 | P24: 1500 | Q24: 1500 | R24: 1500 | S24: 1500 | T24: 2-5 per week
A25: Regular | B25: 15000 | C25: 15000 | D25: 15000 | E25: 15000 | F25: 15000 | G25: 15000 | H25: 15000 | I25: 15000 | J25: 15000 | K25: 15000 | L25: 15000 | M25: 15000 | N25: 15000 | O25: 15000 | P25: 15000 | Q25: 15000 | R25: 15000 | S25: 15000 | T25: 5-10 queries per day
A26: Power | B26: 175000 | C26: 175000 | D26: 175000 | E26: 175000 | F26: 175000 | G26: 175000 | H26: 175000 | I26: 175000 | J26: 175000 | K26: 175000 | L26: 175000 | M26: 175000 | N26: 175000 | O26: 175000 | P26: 175000 | Q26: 175000 | R26: 175000 | S26: 175000 | T26: 2-3 hours
A27: Pro/Prosumer | B27: 800000 | C27: 800000 | D27: 800000 | E27: 800000 | F27: 800000 | G27: 800000 | H27: 800000 | I27: 800000 | J27: 800000 | K27: 800000 | L27: 800000 | M27: 800000 | N27: 800000 | O27: 800000 | P27: 800000 | Q27: 800000 | R27: 800000 | S27: 800000 | T27: some claude code or heavy research
A28: Background multiplier | B28: 1 | C28: =B28*1.05 -> 1.05 | D28: =C28*1.05 -> 1.1025 | E28: =D28*1.05 -> 1.157625 | F28: =E28*1.05 -> 1.2155063 | G28: =F28*1.05 -> 1.2762816 | H28: =G28*1.05 -> 1.3400956 | I28: =H28*1.05 -> 1.4071004 | J28: =I28*1.05 -> 1.4774554 | ... S28: =R28*1.05 -> 2.2920183 | T28: Background tokens not even aware of
A30: Mix
A31: Casual | B31: 0.8 | C31: =B31-0.05 -> 0.75 | D31: =C31-0.05 -> 0.7 | E31: =D31-0.05 -> 0.65 | F31: =E31-0.05 -> 0.6 | G31: =F31-0.05 -> 0.55 | H31: =G31-0.05 -> 0.5 | I31: =H31-0.05 -> 0.45 | J31: =I31-0.05 -> 0.4 | ... R31: =Q31-0.05 -> -9.7144515e-17 | S31: 0
A32: Regular | B32: 0.12 | C32: =B32+0.03 -> 0.15 | D32: =C32+0.03 -> 0.18 | E32: =D32+0.03 -> 0.21 | F32: =E32+0.03 -> 0.24 | G32: =F32+0.03 -> 0.27 | H32: =G32+0.03 -> 0.3 | I32: =H32+0.03 -> 0.33 | J32: =I32+0.03 -> 0.36 | K32: =J32+0.01 -> 0.37 | L32: 0.37 | M32: 0.37 | N32: 0.37 | O32: 0.37 | P32: 0.37 | Q32: 0.37 | R32: 0.37 | S32: 0.37
A33: Power | B33: 0.06 | C33: =1-C31-C32-C34 -> 0.075 | D33: =1-D31-D32-D34 -> 0.09 | E33: =1-E31-E32-E34 -> 0.1 | F33: =1-F31-F32-F34 -> 0.11 | G33: =1-G31-G32-G34 -> 0.12 | H33: =1-H31-H32-H34 -> 0.13 | I33: =1-I31-I32-I34 -> 0.14 | J33: =1-J31-J32-J34 -> 0.15 | ... S33: =1-S31-S32-S34 -> 0.45
A34: Pro/Prosumer | B34: 0.02 | C34: =B34+0.005 -> 0.025 | D34: =C34+0.005 -> 0.03 | E34: =D34+0.01 -> 0.04 | F34: =E34+0.01 -> 0.05 | G34: =F34+0.01 -> 0.06 | H34: =G34+0.01 -> 0.07 | I34: =H34+0.01 -> 0.08 | J34: =I34+0.01 -> 0.09 | K34: =J34+0.01 -> 0.1 | L34: =K34+0.01 -> 0.11 | ... S34: =R34+0.01 -> 0.18
A35: Background
A37: Total Tokens (T's) per year | B37: =B38*365 -> 9690.75 | C37: =C38*365 -> 22756.304 | D37: =D38*365 -> 45967.733 | E37: =E38*365 -> 100979.62 | F37: =F38*365 -> 190380.24 | G37: =G38*365 -> 324479.32 | H37: =H38*365 -> 511249.62 | I37: =I38*365 -> 753028.09 | ... S37: =S38*365 -> 4438202.5
A38: Enterprise Used Per Day (T) | B38: =B22 -> 26.55 | C38: =C39*C40*0.001*C42 -> 62.346037 | D38: =D39*D40*0.001*D42 -> 125.939 | E38: =E39*E40*0.001*E42 -> 276.65649 | F38: =F39*F40*0.001*F42 -> 521.5897 | G38: =G39*G40*0.001*G42 -> 888.98445 | H38: =H39*H40*0.001*H42 -> 1400.6839 | I38: =I39*I40*0.001*I42 -> 2063.0907 | J38: =J39*J40*0.001*J42 -> 2857.6753 | ... S38: =S39*S40*0.001*S42 -> 12159.459 | T38: =(M38/B38)^0.1-1 -> 0.70558334
A39: Knowledge Workers (M) | B39: 1250 | C39: =B39*1.01 -> 1262.5 | D39: =C39*1.01 -> 1275.125 | E39: =D39*1.01 -> 1287.8763 | F39: =E39*1.01 -> 1300.755 | G39: =F39*1.01 -> 1313.7626 | H39: =G39*1.01 -> 1326.9002 | I39: =H39*1.01 -> 1340.1692 | J39: =I39*1.01 -> 1353.5709 | ... S39: =R39*1.01 -> 1480.3805
A40: Tokens/worker per/day | B40: =B38/(B39/1000) -> 21.24 | C40: =B40*(1+C41) -> 32.922 | D40: =C40*(1+D41) -> 49.383 | E40: =D40*(1+E41) -> 71.60535 | F40: =E40*(1+F41) -> 100.24749 | G40: =F40*(1+G41) -> 135.33411 | H40: =G40*(1+H41) -> 175.93434 | I40: =H40*(1+I41) -> 219.91793 | J40: =I40*(1+J41) -> 263.90152 | ... S40: =R40*(1+S41) -> 483.1611
A41: Intensity Growth | C41: 0.55 | D41: 0.5 | E41: 0.45 | F41: 0.4 | G41: 0.35 | H41: 0.3 | I41: 0.25 | J41: 0.2 | K41: 0.15 | L41: 0.1 | M41: 0.08 | N41: 0.05 | O41: 0.05 | P41: 0.05 | Q41: 0.05 | R41: 0.05 | S41: 0.05
A42: Agent Multiplier | B42: 1 | C42: =B42+0.5 -> 1.5 | D42: =C42+0.5 -> 2 | E42: =D42+1 -> 3 | F42: =E42+1 -> 4 | G42: =F42+1 -> 5 | H42: =G42+1 -> 6 | I42: =H42+1 -> 7 | J42: =I42+1 -> 8 | K42: =J42+1 -> 9 | L42: =K42+1 -> 10 | ... S42: =R42+1 -> 17 | T42: This could be much higher
A45: Robotics and Machines
A47: Breakdown of Robots (M's)
A48: AV | B48: 0.01 | C48: 0.05 | D48: 0.15 | E48: 0.5 | F48: 1 | G48: 1.5 | H48: =AVERAGE(I48,G48) -> 2.55 | I48: 3.6 | J48: =AVERAGE(K48,I48) -> 7.65 | K48: 11.7 | L48: =AVERAGE(M48,K48) -> 17.9 | M48: 24.1 | N48: =AVERAGE(O48,M48) -> 31.65 | O48: 39.2 | P48: =AVERAGE(Q48,O48) -> 49.15 | Q48: 59.1 | R48: =AVERAGE(S48,Q48) -> 66.15 | S48: 73.2
A49: Home Robots | B49: 13.8 | C49: 15.5 | D49: 24.8 | E49: 26.5 | F49: 38.2 | G49: 41.8 | H49: =AVERAGE(I49,G49) -> 46.55 | I49: 51.3 | J49: =AVERAGE(K49,I49) -> 56.25 | K49: 61.2 | L49: =AVERAGE(M49,K49) -> 81.05 | M49: 100.9 | N49: =AVERAGE(O49,M49) -> 118.65 | O49: 136.4 | P49: =AVERAGE(Q49,O49) -> 170.55 | Q49: 204.7 | R49: =AVERAGE(S49,Q49) -> 248.2 | S49: 291.7
...

Sheet Bear
B1: 2025 | C1: 2026 | D1: =C1+1 -> 2027 | E1: =D1+1 -> 2028 | F1: =E1+1 -> 2029 | G1: =F1+1 -> 2030 | H1: =G1+1 -> 2031 | I1: =H1+1 -> 2032 | J1: =I1+1 -> 2033 | K1: =J1+1 -> 2034 | ... S1: =R1+1 -> 2042 | T1: Notes
A2: AI Users (M's) | B2: 900 | C2: =B2*1.3 -> 1170 | D2: =C2*1.3 -> 1521 | E2: =D2*1.25 -> 1901.25 | F2: =E2*1.25 -> 2376.5625 | G2: =F2*1.25 -> 2970.7031 | H2: =G2*1.2 -> 3564.8438 | I2: =I3*I4 -> 3851.0919 | J2: =I2*1.1 -> 4236.2011 | K2: =J2*1.1 -> 4659.8212 | L2: =K2*1.1 -> 5125.8033 | M2: =L2*1.1 -> 5638.3837 | N2: =M2*1.1 -> 6202.222 | O2: =N2*1.1 -> 6822.4442 | P2: =O2*1.1 -> 7504.6887 | Q2: =P2*1.1 -> 8255.1575 | ... S2: =R2*1.1 -> 9988.7406
A3: Penetration | B3: =B2/B4 -> 0.15 | C3: =C2/C4 -> 0.1875 | D3: =D2/D4 -> 0.234375 | E3: =E2/E4 -> 0.28722426 | F3: =F2/F4 -> 0.35199052 | G3: =G2/G4 -> 0.43136093 | H3: =H2/H4 -> 0.50748345 | I3: =H3+0.03 -> 0.53748345 | J3: =I3+0.03 -> 0.56748345 | K3: =J3+0.03 -> 0.59748345 | L3: =K3+0.03 -> 0.62748345 | M3: =L3+0.03 -> 0.65748345 | N3: =M3+0.01 -> 0.66748345 | O3: =N3+0.01 -> 0.67748345 | P3: =O3+0.01 -> 0.68748345 | Q3: =P3+0.01 -> 0.69748345 | R3: =Q3+0.01 -> 0.70748345 | S3: =R3+0.01 -> 0.71748345
A4: Internet Users (M) | B4: 6000 | C4: =B4*1.04 -> 6240 | D4: =C4*1.04 -> 6489.6 | E4: =D4*1.02 -> 6619.392 | F4: =E4*1.02 -> 6751.7798 | G4: =F4*1.02 -> 6886.8154 | H4: =G4*1.02 -> 7024.5517 | I4: =H4*1.02 -> 7165.0428 | J4: =I4*1.02 -> 7308.3436 | K4: =J4*1.02 -> 7454.5105 | L4: =K4*1.02 -> 7603.6007 | ... S4: =R4*1.02 -> 8734.1472
A5: Total Population (M) | B5: =C5*0.99 -> 8217 | C5: 8300 | D5: =C5*1.008 -> 8366.4 | E5: =D5*1.008 -> 8433.3312 | F5: =E5*1.008 -> 8500.7978 | G5: =F5*1.008 -> 8568.8042 | H5: =G5*1.007 -> 8628.7859 | I5: =H5*1.007 -> 8689.1874 | J5: =I5*1.007 -> 8750.0117 | K5: =J5*1.006 -> 8802.5117 | L5: =K5*1.006 -> 8855.3268 | M5: =L5*1.006 -> 8908.4588 | N5: =M5*1.006 -> 8961.9095 | O5: =N5*1.006 -> 9015.681 | P5: =O5*1.006 -> 9069.7751 | Q5: =P5*1.006 -> 9124.1937 | R5: =Q5*1.006 -> 9178.9389 | S5: =R5*1.006 -> 9234.0125
A7: Token Usage (T's)/Day | B7: =SUM(B9:B11) -> 53.4622 | C7: =SUM(C9:C11) -> 88.185623 | D7: =SUM(D9:D11) -> 140.46143 | E7: =SUM(E9:E11) -> 215.95073 | F7: =SUM(F9:F11) -> 320.86371 | G7: =SUM(G9:G11) -> 462.82034 | H7: =SUM(H9:H11) -> 637.89528 | I7: =SUM(I9:I11) -> 802.88865 | ... S7: =SUM(S9:S11) -> 5812.9959 | T7: =(M7/B7)^0.1-1 -> 0.43929282
C8: =C7/B7-1 -> 0.64949483 | D8: =D7/C7-1 -> 0.59279282 | E8: =E7/D7-1 -> 0.53743795 | F8: =F7/E7-1 -> 0.48581908 | G8: =G7/F7-1 -> 0.44242032 | H8: =H7/G7-1 -> 0.37827841 | I8: =I7/H7-1 -> 0.25865275 | J8: =J7/I7-1 -> 0.24769611 | ... S8: =S7/R7-1 -> 0.13753786
A9: Retail | B9: =B22 -> 26.55 | C9: =C22 -> 44.84025 | D9: =D22 -> 72.945259 | E9: =E22 -> 118.02511 | F9: =F22 -> 184.15632 | G9: =G22 -> 280.09364 | H9: =H22 -> 401.28745 | I9: =I22 -> 510.05143 | ... S9: =S22 -> 3839.6719 | T9: =(S9/B9)^(1/17)-1 -> 0.33989982
A10: Enterprise | B10: =B38 -> 26.55 | C10: =C38 -> 42.770723 | D10: =D38 -> 66.525582 | E10: =E38 -> 96.082898 | F10: =F38 -> 133.43512 | G10: =G38 -> 177.89571 | H10: =H38 -> 227.28845 | I10: =I38 -> 277.76922 | ... S10: =S38 -> 1296.3363 | T10: =(S10/B10)^(1/17)-1 -> 0.25699207
A11: Robotics | B11: =B58 -> 0.3622 | C11: =C58 -> 0.57465 | D11: =D58 -> 0.990586 | E11: =E58 -> 1.8427156 | F11: =F58 -> 3.2722687 | G11: =G58 -> 4.8309945 | H11: =H58 -> 9.319379 | I11: =I58 -> 15.068008 | ... S11: =S58 -> 676.9877 | T11: =(S11/B11)^(1/17)-1 -> 0.55757497
A13: Mix
A14: Retail | B14: =B9/B$7 -> 0.49661256 | C14: =C9/C$7 -> 0.50847574 | D14: =D9/D$7 -> 0.51932591 | E14: =E9/E$7 -> 0.54653724 | F14: =F9/F$7 -> 0.57393938 | G14: =G9/G$7 -> 0.60518869 | H14: =H9/H$7 -> 0.62908045 | I14: =I9/I$7 -> 0.63527044 | ... S14: =S9/S$7 -> 0.66053236
A15: Enterprise | B15: =B10/B$7 -> 0.49661256 | C15: =C10/C$7 -> 0.48500789 | D15: =D10/D$7 -> 0.47362172 | E15: =E10/E$7 -> 0.44492972 | F15: =F10/F$7 -> 0.41586231 | G15: =G10/G$7 -> 0.38437314 | H15: =H10/H$7 -> 0.35630997 | I15: =I10/I$7 -> 0.34596231 | ... S15: =S10/S$7 -> 0.22300658
A16: Robotics | B16: =B11/B$7 -> 0.0067748802 | C16: =C11/C$7 -> 0.0065163684 | D16: =D11/D$7 -> 0.0070523704 | E16: =E11/E$7 -> 0.0085330371 | F16: =F11/F$7 -> 0.010198313 | G16: =G11/G$7 -> 0.010438164 | H16: =H11/H$7 -> 0.014609575 | I16: =I11/I$7 -> 0.018767245 | ... S16: =S11/S$7 -> 0.11646107
A18: Retail
A19: Total Tokens (B's) per year | B19: =(B22+B38)*365 -> 19381.5 | C19: =(C22+C38)*365 -> 31978.005 | D19: =(D22+D38)*365 -> 50906.857 | E19: =(E22+E38)*365 -> 78149.424 | F19: =(F22+F38)*365 -> 115920.88 | G19: =(G22+G38)*365 -> 167166.11 | H19: =(H22+H38)*365 -> 229430.2 | I19: =(I22+I38)*365 -> 287554.53 | ... S19: =(S22+S38)*365 -> 1874643 | T19: 10Y CAGR
A20: Growth | C20: =C19/B19-1 -> 0.64992415 | D20: =D19/C19-1 -> 0.59193348 | E20: =E19/D19-1 -> 0.53514535 | F20: =F19/E19-1 -> 0.48332349 | G20: =G19/F19-1 -> 0.44207079 | H20: =H19/G19-1 -> 0.3724684 | I20: =I19/H19-1 -> 0.2533421 | J20: =J19/I19-1 -> 0.2395098 | ... S20: =S19/R19-1 -> 0.11607046 | T20: =(M19/B19)^0.1-1 -> 0.43279231
A22: Use per day (T's) | B22: =B23*((B2))*0.000001 -> 26.55 | C22: =C23*((C2))*0.000001 -> 44.84025 | D22: =D23*((D2))*0.000001 -> 72.945259 | E22: =E23*((E2))*0.000001 -> 118.02511 | F22: =F23*((F2))*0.000001 -> 184.15632 | G22: =G23*((G2))*0.000001 -> 280.09364 | H22: =H23*((H2))*0.000001 -> 401.28745 | I22: =I23*((I2))*0.000001 -> 510.05143 | ... S22: =S23*((S2))*0.000001 -> 3839.6719
A23: User Breakdown (tokens/day) | B23: =(SUMPRODUCT(B24:B27,B31:B34))*B28 -> 29500 | C23: =SUMPRODUCT(C24:C27,C31:C34)*C28 -> 38325 | D23: =SUMPRODUCT(D24:D27,D31:D34)*D28 -> 47958.75 | E23: =SUMPRODUCT(E24:E27,E31:E34)*E28 -> 62077.641 | F23: =SUMPRODUCT(F24:F27,F31:F34)*F28 -> 77488.523 | G23: =SUMPRODUCT(G24:G27,G31:G34)*G28 -> 94285.3 | H23: =SUMPRODUCT(H24:H27,H31:H34)*H28 -> 112568.03 | I23: =SUMPRODUCT(I24:I27,I31:I34)*I28 -> 132443.33 | J23: =SUMPRODUCT(J24:J27,J31:J34)*J28 -> 154024.73 | ... S23: =SUMPRODUCT(S24:S27,S31:S34)*S28 -> 384400 | T23: =(M23/B23)^0.1-1 -> 0.23931909
A24: Casual | B24: 1500 | C24: 1500 | D24: 1500 | E24: 1500 | F24: 1500 | G24: 1500 | H24: 1500 | I24: 1500 | J24: 1500 | K24: 1500 | L24: 1500 | M24: 1500 | N24: 1500 | O24: 1500 | P24: 1500 | Q24: 1500 | R24: 1500 | S24: 1500 | T24: 2-5 per week
A25: Regular | B25: 15000 | C25: 15000 | D25: 15000 | E25: 15000 | F25: 15000 | G25: 15000 | H25: 15000 | I25: 15000 | J25: 15000 | K25: 15000 | L25: 15000 | M25: 15000 | N25: 15000 | O25: 15000 | P25: 15000 | Q25: 15000 | R25: 15000 | S25: 15000 | T25: 5-10 queries per day
A26: Power | B26: 175000 | C26: 175000 | D26: 175000 | E26: 175000 | F26: 175000 | G26: 175000 | H26: 175000 | I26: 175000 | J26: 175000 | K26: 175000 | L26: 175000 | M26: 175000 | N26: 175000 | O26: 175000 | P26: 175000 | Q26: 175000 | R26: 175000 | S26: 175000 | T26: 2-3 hours
A27: Pro/Prosumer | B27: 800000 | C27: 800000 | D27: 800000 | E27: 800000 | F27: 800000 | G27: 800000 | H27: 800000 | I27: 800000 | J27: 800000 | K27: 800000 | L27: 800000 | M27: 800000 | N27: 800000 | O27: 800000 | P27: 800000 | Q27: 800000 | R27: 800000 | S27: 800000 | T27: some claude code or heavy research
A28: Background multiplier | B28: 1 | C28: =B28*1.05 -> 1.05 | D28: =C28*1.05 -> 1.1025 | E28: =D28*1.05 -> 1.157625 | F28: =E28*1.05 -> 1.2155063 | G28: =F28*1.05 -> 1.2762816 | H28: =G28*1.05 -> 1.3400956 | I28: =H28*1.05 -> 1.4071004 | J28: =I28*1.05 -> 1.4774554 | ... O28: =N28*1.05 -> 1.8856491 | P28: 2 | Q28: 2 | R28: 2 | S28: 2 | T28: Background tokens not even aware of
A30: Mix
A31: Casual | B31: 0.8 | C31: =B31-0.05 -> 0.75 | D31: =C31-0.05 -> 0.7 | E31: =D31-0.05 -> 0.65 | F31: =E31-0.05 -> 0.6 | G31: =F31-0.05 -> 0.55 | H31: =G31-0.05 -> 0.5 | I31: =H31-0.05 -> 0.45 | J31: =I31-0.05 -> 0.4 | ... O31: =N31-0.05 -> 0.15 | P31: 0.1 | Q31: 0.1 | R31: 0.1 | S31: 0.1
A32: Regular | B32: 0.12 | C32: =B32+0.03 -> 0.15 | D32: =C32+0.03 -> 0.18 | E32: =D32+0.03 -> 0.21 | F32: =E32+0.03 -> 0.24 | G32: =F32+0.03 -> 0.27 | H32: =G32+0.03 -> 0.3 | I32: =H32+0.03 -> 0.33 | J32: =I32+0.03 -> 0.36 | K32: =J32+0.01 -> 0.37 | L32: 0.37 | M32: 0.37 | N32: 0.37 | O32: 0.37 | P32: 0.37 | Q32: 0.37 | R32: 0.37 | S32: 0.37
A33: Power | B33: 0.06 | C33: =1-C31-C32-C34 -> 0.075 | D33: =1-D31-D32-D34 -> 0.09 | E33: =1-E31-E32-E34 -> 0.1 | F33: =1-F31-F32-F34 -> 0.11 | G33: =1-G31-G32-G34 -> 0.12 | H33: =1-H31-H32-H34 -> 0.13 | I33: =1-I31-I32-I34 -> 0.14 | J33: =1-J31-J32-J34 -> 0.15 | ... S33: =1-S31-S32-S34 -> 0.38
A34: Pro/Prosumer | B34: 0.02 | C34: =B34+0.005 -> 0.025 | D34: =C34+0.005 -> 0.03 | E34: =D34+0.01 -> 0.04 | F34: =E34+0.01 -> 0.05 | G34: =F34+0.01 -> 0.06 | H34: =G34+0.01 -> 0.07 | I34: =H34+0.01 -> 0.08 | J34: =I34+0.01 -> 0.09 | K34: =J34+0.01 -> 0.1 | L34: =K34+0.01 -> 0.11 | ... O34: =N34+0.01 -> 0.14 | P34: 0.15 | Q34: 0.15 | R34: 0.15 | S34: 0.15
A35: Background
A37: Total Tokens (T's) per year | B37: =B38*365 -> 9690.75 | C37: =C38*365 -> 15611.314 | D37: =D38*365 -> 24281.837 | E37: =E38*365 -> 35070.258 | F37: =F38*365 -> 48703.82 | G37: =G38*365 -> 64931.933 | H37: =H38*365 -> 82960.285 | I37: =I38*365 -> 101385.76 | ... S37: =S38*365 -> 473162.76
A38: Enterprise Used Per Day (T) | B38: =B22 -> 26.55 | C38: =C39*C40*0.001*C42 -> 42.770723 | D38: =D39*D40*0.001*D42 -> 66.525582 | E38: =E39*E40*0.001*E42 -> 96.082898 | F38: =F39*F40*0.001*F42 -> 133.43512 | G38: =G39*G40*0.001*G42 -> 177.89571 | H38: =H39*H40*0.001*H42 -> 227.28845 | I38: =I39*I40*0.001*I42 -> 277.76922 | J38: =J39*J40*0.001*J42 -> 324.03168 | ... S38: =S39*S40*0.001*S42 -> 1296.3363 | T38: =(M38/B38)^0.1-1 -> 0.34500315
A39: Knowledge Workers (M) | B39: 1250 | C39: =B39*1.01 -> 1262.5 | D39: =C39*1.01 -> 1275.125 | E39: =D39*1.01 -> 1287.8763 | F39: =E39*1.01 -> 1300.755 | G39: =F39*1.01 -> 1313.7626 | H39: =G39*1.01 -> 1326.9002 | I39: =H39*1.01 -> 1340.1692 | J39: =I39*1.01 -> 1353.5709 | ... S39: =R39*1.01 -> 1480.3805
A40: Tokens/worker per/day | B40: =B38/(B39/1000) -> 21.24 | C40: =B40*(1+C41) -> 30.798 | D40: =C40*(1+D41) -> 43.1172 | E40: =D40*(1+E41) -> 56.05236 | F40: =E40*(1+F41) -> 70.06545 | G40: =F40*(1+G41) -> 84.07854 | H40: =G40*(1+H41) -> 96.690321 | I40: =H40*(1+I41) -> 106.35935 | J40: =I40*(1+J41) -> 111.67732 | ... S40: =R40*(1+S41) -> 173.24818
A41: Intensity Growth | C41: 0.45 | D41: 0.4 | E41: 0.3 | F41: 0.25 | G41: 0.2 | H41: 0.15 | I41: 0.1 | J41: 0.05 | K41: 0.05 | L41: 0.05 | M41: 0.05 | N41: 0.05 | O41: 0.05 | P41: 0.05 | Q41: 0.05 | R41: 0.05 | S41: 0.05
A42: Agent Multiplier | B42: 1 | C42: =B42*1.1 -> 1.1 | D42: =C42*1.1 -> 1.21 | E42: =D42*1.1 -> 1.331 | F42: =E42*1.1 -> 1.4641 | G42: =F42*1.1 -> 1.61051 | H42: =G42*1.1 -> 1.771561 | I42: =H42*1.1 -> 1.9487171 | J42: =I42*1.1 -> 2.1435888 | ... S42: =R42*1.1 -> 5.0544703 | T42: This could be much higher
A45: Robotics and Machines
A47: Breakdown of Robots (M's)
A48: AV | B48: 0.01 | C48: 0.05 | D48: 0.15 | E48: 0.5 | F48: 1 | G48: 1.5 | H48: =AVERAGE(I48,G48) -> 2.55 | I48: 3.6 | J48: =AVERAGE(K48,I48) -> 7.65 | K48: 11.7 | L48: =AVERAGE(M48,K48) -> 17.9 | M48: 24.1 | N48: =AVERAGE(O48,M48) -> 31.65 | O48: 39.2 | P48: =AVERAGE(Q48,O48) -> 49.15 | Q48: 59.1 | R48: =AVERAGE(S48,Q48) -> 66.15 | S48: 73.2
A49: Home Robots | B49: 13.8 | C49: 15.5 | D49: 24.8 | E49: 26.5 | F49: 38.2 | G49: 41.8 | H49: =AVERAGE(I49,G49) -> 46.55 | I49: 51.3 | J49: =AVERAGE(K49,I49) -> 56.25 | K49: 61.2 | L49: =AVERAGE(M49,K49) -> 81.05 | M49: 100.9 | N49: =AVERAGE(O49,M49) -> 118.65 | O49: 136.4 | P49: =AVERAGE(Q49,O49) -> 170.55 | Q49: 204.7 | R49: =AVERAGE(S49,Q49) -> 248.2 | S49: 291.7
...

Sheet Macro Levers
A1: Macro Levers (ITEM 8 / ITEM 9)
A2: Edit column B. Read by dashboard + export. | B2: see | C2: research/model_corrections_2026-06-23.md (defaults = committed base, 332.4 GW @ 2029)
A3: param_key | B3: value | C3: notes
A4: use_flops_demand | B4: 0 | C4: 1=ON: rebase demand on FLOPs (tokens x 2N). 0=committed token basis
A5: flops_n_frontier_b | B5: 500 | C5: active params (billions), frontier tier
A6: flops_n_mid_b | B6: 70 | C6: active params (billions), mid tier
A7: flops_n_small_b | B7: 8 | C7: active params (billions), small tier
A8: flops_mix2025_frontier | B8: 0.55 | C8: 2025 token share, frontier
A9: flops_mix2025_mid | B9: 0.3 | C9: 2025 token share, mid
A10: flops_mix2025_small | B10: 0.15 | C10: 2025 token share, small
A11: flops_mix2040_frontier | B11: 0.15 | C11: 2040 token share, frontier
A12: flops_mix2040_mid | B12: 0.35 | C12: 2040 token share, mid
A13: flops_mix2040_small | B13: 0.5 | C13: 2040 token share, small
A14: flops_mfu | B14: 0.35 | C14: model FLOPs utilization (cancels in 2025 anchor)
A15: capacity_retirement_rate | B15: 0 | C15: ITEM 9: 0=plateau (base), 1=cliff, 0..1=controlled decline

Sheet FLOPs to Power
A1: FLOPs to Power · LIVE formulas (tokens -> FLOPs -> power)
A2: Edit the inputs below; FLOPs and power recompute. Tokens are linked live to the 'Efficiency Overlay' sheet.
A3: anchor_GW_2025 | B3: 70
A4: retail_uplift_to_1400_user_basis | B4: =1400/'Efficiency Overlay'!C9-1 -> 0.27272727
A5: capacity_retirement_rate_per_yr (ITEM 9: 0=plateau, 1=cliff) | B5: 0
A6: training share = 6N FLOPs/token vs 2N inference. A CONSTANT split cancels in the re-anchor; VARY it by year to bend the power curve.
A7: year | B7: tokens_day_T | C7: training_share | D7: avg_N_active_B | E7: fleet_TFLOP_per_W | F7: FLOPs_per_token | G7: FLOPs_per_day | H7: power_raw_GW | I7: power_GW_floored
A8: 2025 | B8: ='Efficiency Overlay'!C5+'Efficiency Overlay'!C7*$B$4 -> 134.9222 | C8: 0 | D8: 297.2 | E8: 9 | F8: =(2*(1-C8)+6*C8)*D8*1000000000 -> 594400000000 | G8: =B8*1000000000000*F8 -> 8.0197756e+25 | H8: =(G8/E8)/($G$8/$E$8)*$B$3 -> 70 | I8: =H8 -> 70
A9: 2026 | B9: ='Efficiency Overlay'!D5+'Efficiency Overlay'!D7*$B$4 -> 460.84402 | C9: 0 | D9: 284.28667 | E9: 11 | F9: =(2*(1-C9)+6*C9)*D9*1000000000 -> 5.6857333e+11 | G9: =B9*1000000000000*F9 -> 2.6202362e+26 | H9: =(G9/E9)/($G$8/$E$8)*$B$3 -> 187.12254 | I9: =MAX(H9,I8*(1-$B$5)) -> 187.12254
A10: 2027 | B10: ='Efficiency Overlay'!E5+'Efficiency Overlay'!E7*$B$4 -> 763.61328 | C10: 0 | D10: 271.37333 | E10: 14 | F10: =(2*(1-C10)+6*C10)*D10*1000000000 -> 5.4274667e+11 | G10: =B10*1000000000000*F10 -> 4.1444856e+26 | H10: =(G10/E10)/($G$8/$E$8)*$B$3 -> 232.55246 | I10: =MAX(H10,I9*(1-$B$5)) -> 232.55246
A11: 2028 | B11: ='Efficiency Overlay'!F5+'Efficiency Overlay'!F7*$B$4 -> 1359.8027 | C11: 0 | D11: 258.46 | E11: 18 | F11: =(2*(1-C11)+6*C11)*D11*1000000000 -> 5.1692e+11 | G11: =B11*1000000000000*F11 -> 7.0290923e+26 | H11: =(G11/E11)/($G$8/$E$8)*$B$3 -> 306.76448 | I11: =MAX(H11,I10*(1-$B$5)) -> 306.76448
A12: 2029 | B12: ='Efficiency Overlay'!G5+'Efficiency Overlay'!G7*$B$4 -> 2172.7938 | C12: 0 | D12: 245.54667 | E12: 21.5 | F12: =(2*(1-C12)+6*C12)*D12*1000000000 -> 4.9109333e+11 | G12: =B12*1000000000000*F12 -> 1.0670445e+27 | H12: =(G12/E12)/($G$8/$E$8)*$B$3 -> 389.87233 | I12: =MAX(H12,I11*(1-$B$5)) -> 389.87233
A13: 2030 | B13: ='Efficiency Overlay'!H5+'Efficiency Overlay'!H7*$B$4 -> 3253.5841 | C13: 0 | D13: 232.63333 | E13: 25 | F13: =(2*(1-C13)+6*C13)*D13*1000000000 -> 4.6526667e+11 | G13: =B13*1000000000000*F13 -> 1.5137842e+27 | H13: =(G13/E13)/($G$8/$E$8)*$B$3 -> 475.66621 | I13: =MAX(H13,I12*(1-$B$5)) -> 475.66621
A14: 2031 | B14: ='Efficiency Overlay'!I5+'Efficiency Overlay'!I7*$B$4 -> 4573.0374 | C14: 0 | D14: 219.72 | E14: 28 | F14: =(2*(1-C14)+6*C14)*D14*1000000000 -> 439440000000 | G14: =B14*1000000000000*F14 -> 2.0095756e+27 | H14: =(G14/E14)/($G$8/$E$8)*$B$3 -> 563.79944 | I14: =MAX(H14,I13*(1-$B$5)) -> 563.79944
A15: 2032 | B15: ='Efficiency Overlay'!J5+'Efficiency Overlay'!J7*$B$4 -> 5901.4175 | C15: 0 | D15: 206.80667 | E15: 31 | F15: =(2*(1-C15)+6*C15)*D15*1000000000 -> 4.1361333e+11 | G15: =B15*1000000000000*F15 -> 2.440905e+27 | H15: =(G15/E15)/($G$8/$E$8)*$B$3 -> 618.53961 | I15: =MAX(H15,I14*(1-$B$5)) -> 618.53961
A16: 2033 | B16: ='Efficiency Overlay'!K5+'Efficiency Overlay'!K7*$B$4 -> 7334.6159 | C16: 0 | D16: 193.89333 | E16: 34 | F16: =(2*(1-C16)+6*C16)*D16*1000000000 -> 3.8778667e+11 | G16: =B16*1000000000000*F16 -> 2.8442663e+27 | H16: =(G16/E16)/($G$8/$E$8)*$B$3 -> 657.1578 | I16: =MAX(H16,I15*(1-$B$5)) -> 657.1578
A17: 2034 | B17: ='Efficiency Overlay'!L5+'Efficiency Overlay'!L7*$B$4 -> 8998.7061 | C17: 0 | D17: 180.98 | E17: 37 | F17: =(2*(1-C17)+6*C17)*D17*1000000000 -> 3.6196e+11 | G17: =B17*1000000000000*F17 -> 3.2571717e+27 | H17: =(G17/E17)/($G$8/$E$8)*$B$3 -> 691.53992 | I17: =MAX(H17,I16*(1-$B$5)) -> 691.53992
A18: 2035 | B18: ='Efficiency Overlay'!M5+'Efficiency Overlay'!M7*$B$4 -> 10620.446 | C18: 0 | D18: 168.06667 | E18: 40 | F18: =(2*(1-C18)+6*C18)*D18*1000000000 -> 3.3613333e+11 | G18: =B18*1000000000000*F18 -> 3.5698858e+27 | H18: =(G18/E18)/($G$8/$E$8)*$B$3 -> 701.08822 | I18: =MAX(H18,I17*(1-$B$5)) -> 701.08822
A19: 2036 | B19: ='Efficiency Overlay'!N5+'Efficiency Overlay'!N7*$B$4 -> 12433.273 | C19: 0 | D19: 155.15333 | E19: 42.857143 | F19: =(2*(1-C19)+6*C19)*D19*1000000000 -> 3.1030667e+11 | G19: =B19*1000000000000*F19 -> 3.8581276e+27 | H19: =(G19/E19)/($G$8/$E$8)*$B$3 -> 707.18282 | I19: =MAX(H19,I18*(1-$B$5)) -> 707.18282
A20: 2037 | B20: ='Efficiency Overlay'!O5+'Efficiency Overlay'!O7*$B$4 -> 14482.723 | C20: 0 | D20: 142.24 | E20: 45.714286 | F20: =(2*(1-C20)+6*C20)*D20*1000000000 -> 284480000000 | G20: =B20*1000000000000*F20 -> 4.120045e+27 | H20: =(G20/E20)/($G$8/$E$8)*$B$3 -> 707.99201 | I20: =MAX(H20,I19*(1-$B$5)) -> 707.99201
A21: 2038 | B21: ='Efficiency Overlay'!P5+'Efficiency Overlay'!P7*$B$4 -> 16709.133 | C21: 0 | D21: 129.32667 | E21: 48.571429 | F21: =(2*(1-C21)+6*C21)*D21*1000000000 -> 2.5865333e+11 | G21: =B21*1000000000000*F21 -> 4.3218729e+27 | H21: =(G21/E21)/($G$8/$E$8)*$B$3 -> 698.98756 | I21: =MAX(H21,I20*(1-$B$5)) -> 707.99201
A22: 2039 | B22: ='Efficiency Overlay'!Q5+'Efficiency Overlay'!Q7*$B$4 -> 18373.445 | C22: 0 | D22: 116.41333 | E22: 51.428571 | F22: =(2*(1-C22)+6*C22)*D22*1000000000 -> 2.3282667e+11 | G22: =B22*1000000000000*F22 -> 4.277828e+27 | H22: =(G22/E22)/($G$8/$E$8)*$B$3 -> 653.42717 | I22: =MAX(H22,I21*(1-$B$5)) -> 707.99201
A23: 2040 | B23: ='Efficiency Overlay'!R5+'Efficiency Overlay'!R7*$B$4 -> 20019.811 | C23: 0 | D23: 103.5 | E23: 54.285714 | F23: =(2*(1-C23)+6*C23)*D23*1000000000 -> 2.07e+11 | G23: =B23*1000000000000*F23 -> 4.1441009e+27 | H23: =(G23/E23)/($G$8/$E$8)*$B$3 -> 599.68488 | I23: =MAX(H23,I22*(1-$B$5)) -> 707.99201
A24: 2041 | B24: ='Efficiency Overlay'!S5+'Efficiency Overlay'!S7*$B$4 -> 21860.124 | C24: 0 | D24: 103.5 | E24: 57.142857 | F24: =(2*(1-C24)+6*C24)*D24*1000000000 -> 2.07e+11 | G24: =B24*1000000000000*F24 -> 4.5250457e+27 | H24: =(G24/E24)/($G$8/$E$8)*$B$3 -> 622.07013 | I24: =MAX(H24,I23*(1-$B$5)) -> 707.99201
A25: 2042 | B25: ='Efficiency Overlay'!T5+'Efficiency Overlay'!T7*$B$4 -> 23789.689 | C25: 0 | D25: 103.5 | E25: 60 | F25: =(2*(1-C25)+6*C25)*D25*1000000000 -> 2.07e+11 | G25: =B25*1000000000000*F25 -> 4.9244656e+27 | H25: =(G25/E25)/($G$8/$E$8)*$B$3 -> 644.74234 | I25: =MAX(H25,I24*(1-$B$5)) -> 707.99201

Sheet Duration Lens
A1: AI POWER DEMAND — THE DURATION LENS
A2: Token base (committed headline) vs the FLOPs lens. A token's power cost varies ~50x by model, so convert tokens -> FLOPs -> power. Live mechanics + stress-test inputs are on the 'FLOPs to Power' tab.
A4: 1. THE QUESTION
A5: How big does AI power demand get, and how long does the shortage last? FLOPs/token = 2 x active params; that is the honest power unit a token-count model cannot see (routing/orchestration moves it).
A7: 2. THE CONVERSION (one row = one year; full live version on 'FLOPs to Power')
A8: step | B8: 2025 | C8: 2035
A9: tokens/day (T) | B9: ='FLOPs to Power'!B8 -> 134.9222 | C9: ='FLOPs to Power'!B18 -> 10620.446
A10: x FLOPs per token (2 x N_active) | B10: ='FLOPs to Power'!F8 -> 594400000000 | C10: ='FLOPs to Power'!F18 -> 3.3613333e+11
A11: -> FLOPs per day | B11: ='FLOPs to Power'!G8 -> 8.0197756e+25 | C11: ='FLOPs to Power'!G18 -> 3.5698858e+27
A12: / chip efficiency (TFLOP per W) | B12: ='FLOPs to Power'!E8 -> 9 | C12: ='FLOPs to Power'!E18 -> 40
A13: -> power (GW) | B13: ='FLOPs to Power'!I8 -> 70 | C13: ='FLOPs to Power'!I18 -> 701.08822
A15: 3. THE TUG-OF-WAR (why power grows ~10x, not ~176x)
A16: Tokens grow ~176x to 2042. But model size N falls ~3x (routing to smaller models) and chip TFLOP/W rises ~7x. Together they absorb most of it, so power grows ~10x.
A18: 4. TOKEN BASE vs FLOPs LENS
A19: metric | B19: Token base | C19: FLOPs lens
A20: Peak gap (GW) | B20: 332 | C20: 278
A21: Peak year | B21: 2029 | C21: 2031
A22: Demand floor 2042 (GW) | B22: 549 | C22: =ROUND('FLOPs to Power'!I25,0) -> 708
A23: Gap closes (overshoot) | B23: 2034 | C23: 2036
A24: Read | B24: timing / peak | C24: duration / higher floor
A26: 5. CHART THIS (select A27:D45, then Insert > Line Chart)
A27: year | B27: Token demand (GW) | C27: FLOPs demand (GW) | D27: Supply (GW)
A28: 2025 | B28: 70 | C28: =ROUND('FLOPs to Power'!I8,1) -> 70 | D28: 70
A29: 2026 | B29: 219.2 | C29: =ROUND('FLOPs to Power'!I9,1) -> 187.1 | D29: 85.4
A30: 2027 | B30: 305.7 | C30: =ROUND('FLOPs to Power'!I10,1) -> 232.6 | D30: 104.2
A31: 2028 | B31: 427 | C31: =ROUND('FLOPs to Power'!I11,1) -> 306.8 | D31: 135.4
A32: 2029 | B32: 508.5 | C32: =ROUND('FLOPs to Power'!I12,1) -> 389.9 | D32: 176.1
A33: 2030 | B33: 548.9 | C33: =ROUND('FLOPs to Power'!I13,1) -> 475.7 | D33: 228.9
A34: 2031 | B34: 548.9 | C34: =ROUND('FLOPs to Power'!I14,1) -> 563.8 | D34: 286.1
A35: 2032 | B35: 548.9 | C35: =ROUND('FLOPs to Power'!I15,1) -> 618.5 | D35: 357.7
A36: 2033 | B36: 548.9 | C36: =ROUND('FLOPs to Power'!I16,1) -> 657.2 | D36: 447.1
A37: 2034 | B37: 548.9 | C37: =ROUND('FLOPs to Power'!I17,1) -> 691.5 | D37: 558.8
A38: 2035 | B38: 548.9 | C38: =ROUND('FLOPs to Power'!I18,1) -> 701.1 | D38: 698.6
A39: 2036 | B39: 548.9 | C39: =ROUND('FLOPs to Power'!I19,1) -> 707.2 | D39: 803.3
... A45: 2042 | B45: 548.9 | C45: =ROUND('FLOPs to Power'!I25,1) -> 708 | D45: 1858.2
A47: 6. STRESS-TEST IT
A48: Edit inputs on 'FLOPs to Power' (anchor, training share, N, TFLOP/W, retirement) — the FLOPs column above and this chart's FLOPs line update live. Broader levers on 'Macro Levers'.
A50: 7. THE TAKEAWAY
A51: The FLOPs lens does NOT raise the peak (~278 vs 332). It raises the FLOOR (~708 vs 549, +29%) and extends the TIGHTNESS (gap closes ~2036 vs 2034). The power/grid/cooling case is about DURATION, not magnitude.

Sheet Operating Model
A1: OPERATING MODEL — Demand / Supply / Gap (Bull / Base / Bear)
A2: Set scenario in B3 (1=Bull, 2=Base, 3=Bear). Everything recomputes. Base inputs (tokens, N, TFLOP/W, training) live on 'FLOPs to Power'; this sheet overlays the scenario and adds supply + gap.
A3: SCENARIO (1=Bull 2=Base 3=Bear) | B3: 2
A4: active scenario | B4: =CHOOSE(B3,"Bull","Base","Bear") -> Base
A6: SCENARIO INPUTS | B6: Bull | C6: Base | D6: Bear
A7: anchor GW 2025 | B7: 70 | C7: 70 | D7: 70
A8: token growth adj (per yr) | B8: 0.02 | C8: 0 | D8: -0.02
A9: efficiency adj (per yr, + = faster = less power) | B9: -0.015 | C9: 0 | D9: 0.03
A10: capacity retirement (per yr) | B10: 0 | C10: 0 | D10: 0.08
A11: supply build scale (x phase rates) | B11: 0.85 | C11: 1 | D11: 1.15
A13: SUPPLY PHASE RATES (per yr, editable)
A14: 2026-2027 | B14: 0.22
A15: 2028-2030 | B15: 0.3
A16: 2031-2035 | B16: 0.25
A17: 2036-2042 | B17: 0.15
A19: ACTIVE (from scenario)
A20: anchor GW | B20: =CHOOSE($B$3,B7,C7,D7) -> 70
A21: token growth adj | B21: =CHOOSE($B$3,B8,C8,D8) -> 0
A22: efficiency adj | B22: =CHOOSE($B$3,B9,C9,D9) -> 0
A23: retirement rate | B23: =CHOOSE($B$3,B10,C10,D10) -> 0
A24: supply build scale | B24: =CHOOSE($B$3,B11,C11,D11) -> 1
A27: year | B27: tokens/day T | C27: FLOPs/token | D27: eff TFLOP/W | E27: raw demand GW | F27: demand floored GW | G27: supply GW | H27: GAP GW | I27: _bal | J27: _over
A28: 2025 | B28: ='FLOPs to Power'!B8*(1+$B$21)^0 -> 134.9222 | C28: ='FLOPs to Power'!F8 -> 594400000000 | D28: ='FLOPs to Power'!E8*(1+$B$22)^0 -> 9 | E28: =(B28*C28/D28)/(B28*C28/D28)*$B$20 -> 70 | F28: =E28 -> 70 | G28: =$B$20 -> 70 | H28: =F28-G28 -> 0 | I28: =IF(AND(A28>=$B$48,H28<30),A28,99999) -> 99999 | J28: =IF(H28<0,A28,99999) -> 99999
